<robot name="planar_2d">
    <link name="base_link">
    	  <visual>
	      <origin xyz="0 0 .05" rpy="0 0 0" />
     	      <geometry>
		    <cylinder radius=".02" length=".1" />
     	      </geometry>
	      <material name="Red">
       		    <color rgba="1.0 0.0 0.0 1.0"/>
     	      </material>
   	   </visual>        
    </link>

    <link name="link1">
    	  <visual>
	      <origin xyz="0.0635635 0 0" rpy="0 1.57079 0" />
     	      <geometry>
		    <cylinder radius=".01905" length="0.127127"/>
     	      </geometry>
	      <material name="Cyan">
       		    <color rgba="0 1.0 1.0 1.0"/>
     	      </material>
   	   </visual>
    </link>

    <link name="link2">
    	  <visual>
	      <origin xyz="0.0733425 0 0" rpy="0 1.57079 0" />
     	      <geometry>
		    <cylinder radius="0.01905" length="0.146685"/>
     	      </geometry>
	      <material name="Cyan">
       		    <color rgba="0 1.0 1.0 1.0"/>
     	      </material>
   	   </visual>
    </link>

    <link name="link3"/>

    <joint name="joint1" type="continuous">
    	   <parent link="base_link"/>
	   <child link="link1"/>
	   <origin xyz="0 0 .05" rpy="0 0 0"/>
	   <axis xyz="0 0 1"/>
    </joint>

    <joint name="joint2" type="continuous">
    	   <parent link="link1"/>
	   <child link="link2"/>
	   <origin xyz="0.127127 0 0" rpy="0 0 0"/>
	   <axis xyz="0 0 1"/>
    </joint>
    <joint name="end_effector" type="fixed">
    	   <parent link="link2"/>
	   <child link="link3"/>
	   <origin xyz="0.146685 0 0" rpy="0 0 0"/>
	   <axis xyz="0 0 1"/>
    </joint>
</robot>